Đã kết nối tới CSDL và sẵn sàng truy vấn

0: 480x640 1 class_0, 259.3ms
Speed: 3.8ms preprocess, 259.3ms inference, 1.0ms postprocess per image at shape (1, 3, 480, 640)
[2024/05/10 01:48:32] ppocr WARNING: Since the angle classifier is not initialized, it will not be used during the forward process
image/image_result/10-05-24/license/license2024-05-10-01-48-32.png
Lỗi:  23000
đã rollback ở ngoại lệ

0: 480x640 1 class_0, 214.5ms
Speed: 1.0ms preprocess, 214.5ms inference, 1.0ms postprocess per image at shape (1, 3, 480, 640)
[2024/05/10 01:48:40] ppocr WARNING: Since the angle classifier is not initialized, it will not be used during the forward process
image/image_result/10-05-24/license/license2024-05-10-01-48-40.png
Lỗi:  23000
đã rollback ở ngoại lệ

0: 480x640 1 class_0, 238.7ms
Speed: 2.0ms preprocess, 238.7ms inference, 2.0ms postprocess per image at shape (1, 3, 480, 640)
[2024/05/10 01:48:41] ppocr WARNING: Since the angle classifier is not initialized, it will not be used during the forward process
image/image_result/10-05-24/license/license2024-05-10-01-48-41.png
Lỗi:  23000
đã rollback ở ngoại lệ

0: 480x640 1 class_0, 232.3ms
Speed: 2.0ms preprocess, 232.3ms inference, 1.0ms postprocess per image at shape (1, 3, 480, 640)
[2024/05/10 01:48:41] ppocr WARNING: Since the angle classifier is not initialized, it will not be used during the forward process
23000Exception in Tkinter callback
Traceback (most recent call last):
  File "C:\Program Files\WindowsApps\PythonSoftwareFoundation.Python.3.11_3.11.2544.0_x64__qbz5n2kfra8p0\Lib\tkinter\__init__.py", line 1967, in __call__
    return self.func(*args)
           ^^^^^^^^^^^^^^^^
  File "D:\Hieu\dacn\license_plate_app\tkButton.py", line 334, in get_license
    self.setup_IN_success()
  File "D:\Hieu\dacn\license_plate_app\tkButton.py", line 199, in setup_IN_success
    self.my_DB.info_insert_IN_onetime(self.id_card, self.now, self.license_plate, status="IN",result= "OK", lane=1, time_out= 0,
  File "D:\Hieu\dacn\license_plate_app\license_plate_DB.py", line 103, in info_insert_IN_onetime
    cursor.execute(info_insert_IN_onetime_quert, id_card, time_in, license_plate, result, lane, in_background, in_license,
pyodbc.IntegrityError: ('23000', "[23000] [Microsoft][ODBC Driver 18 for SQL Server][SQL Server]Violation of PRIMARY KEY constraint 'PK__License___CAF38E519077C596'. Cannot insert duplicate key in object 'dbo.License_Plate'. The duplicate key value is (12-B1168.88). (2627) (SQLExecDirectW); [23000] [Microsoft][ODBC Driver 18 for SQL Server][SQL Server]The statement has been terminated. (3621)")
23000Exception in Tkinter callback
Traceback (most recent call last):
  File "C:\Program Files\WindowsApps\PythonSoftwareFoundation.Python.3.11_3.11.2544.0_x64__qbz5n2kfra8p0\Lib\tkinter\__init__.py", line 1967, in __call__
    return self.func(*args)
           ^^^^^^^^^^^^^^^^
  File "D:\Hieu\dacn\license_plate_app\tkButton.py", line 334, in get_license
    self.setup_IN_success()
  File "D:\Hieu\dacn\license_plate_app\tkButton.py", line 199, in setup_IN_success
    self.my_DB.info_insert_IN_onetime(self.id_card, self.now, self.license_plate, status="IN",result= "OK", lane=1, time_out= 0,
  File "D:\Hieu\dacn\license_plate_app\license_plate_DB.py", line 103, in info_insert_IN_onetime
    cursor.execute(info_insert_IN_onetime_quert, id_card, time_in, license_plate, result, lane, in_background, in_license,
pyodbc.IntegrityError: ('23000', "[23000] [Microsoft][ODBC Driver 18 for SQL Server][SQL Server]Violation of PRIMARY KEY constraint 'PK__License___CAF38E519077C596'. Cannot insert duplicate key in object 'dbo.License_Plate'. The duplicate key value is (12-B1168.88). (2627) (SQLExecDirectW); [23000] [Microsoft][ODBC Driver 18 for SQL Server][SQL Server]The statement has been terminated. (3621)")
23000Exception in Tkinter callback
Traceback (most recent call last):
  File "C:\Program Files\WindowsApps\PythonSoftwareFoundation.Python.3.11_3.11.2544.0_x64__qbz5n2kfra8p0\Lib\tkinter\__init__.py", line 1967, in __call__
    return self.func(*args)
           ^^^^^^^^^^^^^^^^
  File "D:\Hieu\dacn\license_plate_app\tkButton.py", line 334, in get_license
    self.setup_IN_success()
  File "D:\Hieu\dacn\license_plate_app\tkButton.py", line 199, in setup_IN_success
    self.my_DB.info_insert_IN_onetime(self.id_card, self.now, self.license_plate, status="IN",result= "OK", lane=1, time_out= 0,
  File "D:\Hieu\dacn\license_plate_app\license_plate_DB.py", line 103, in info_insert_IN_onetime
    cursor.execute(info_insert_IN_onetime_quert, id_card, time_in, license_plate, result, lane, in_background, in_license,
pyodbc.IntegrityError: ('23000', "[23000] [Microsoft][ODBC Driver 18 for SQL Server][SQL Server]Violation of PRIMARY KEY constraint 'PK__License___CAF38E519077C596'. Cannot insert duplicate key in object 'dbo.License_Plate'. The duplicate key value is (12-B1168.88). (2627) (SQLExecDirectW); [23000] [Microsoft][ODBC Driver 18 for SQL Server][SQL Server]The statement has been terminated. (3621)")
23000Exception in Tkinter callback
Traceback (most recent call last):
  File "C:\Program Files\WindowsApps\PythonSoftwareFoundation.Python.3.11_3.11.2544.0_x64__qbz5n2kfra8p0\Lib\tkinter\__init__.py", line 1967, in __call__
    return self.func(*args)
           ^^^^^^^^^^^^^^^^
  File "D:\Hieu\dacn\license_plate_app\tkButton.py", line 334, in get_license
    self.setup_IN_success()
  File "D:\Hieu\dacn\license_plate_app\tkButton.py", line 199, in setup_IN_success
    self.my_DB.info_insert_IN_onetime(self.id_card, self.now, self.license_plate, status="IN",result= "OK", lane=1, time_out= 0,
  File "D:\Hieu\dacn\license_plate_app\license_plate_DB.py", line 103, in info_insert_IN_onetime
    cursor.execute(info_insert_IN_onetime_quert, id_card, time_in, license_plate, result, lane, in_background, in_license,
pyodbc.IntegrityError: ('23000', "[23000] [Microsoft][ODBC Driver 18 for SQL Server][SQL Server]Violation of PRIMARY KEY constraint 'PK__License___CAF38E519077C596'. Cannot insert duplicate key in object 'dbo.License_Plate'. The duplicate key value is (12-B1168.88). (2627) (SQLExecDirectW); [23000] [Microsoft][ODBC Driver 18 for SQL Server][SQL Server]The statement has been terminated. (3621)")
Exception in Tkinter callback
Traceback (most recent call last):
  File "C:\Program Files\WindowsApps\PythonSoftwareFoundation.Python.3.11_3.11.2544.0_x64__qbz5n2kfra8p0\Lib\tkinter\__init__.py", line 1967, in __call__
    return self.func(*args)
           ^^^^^^^^^^^^^^^^
  File "C:\Program Files\WindowsApps\PythonSoftwareFoundation.Python.3.11_3.11.2544.0_x64__qbz5n2kfra8p0\Lib\tkinter\__init__.py", line 861, in callit
    func(*args)
  File "D:\Hieu\dacn\license_plate_app\tkCamera.py", line 57, in update_frame
    resized_image= frame.resize((width,height), PIL.Image.Resampling.LANCZOS)
                   ^^^^^^^^^^^^^^^^^^^^^^^^^^^^^^^^^^^^^^^^^^^^^^^^^^^^^^^^^^
  File "C:\Users\Hann\AppData\Local\Packages\PythonSoftwareFoundation.Python.3.11_qbz5n2kfra8p0\LocalCache\local-packages\Python311\site-packages\PIL\Image.py", line 2222, in resize
    return self._new(self.im.resize(size, resample, box))
                     ^^^^^^^^^^^^^^^^^^^^^^^^^^^^^^^^^^^
KeyboardInterrupt
image/image_result/10-05-24/license/license2024-05-10-01-48-41.png
Lỗi:  23000
đã rollback ở ngoại lệ
Đã kết nối tới CSDL và sẵn sàng truy vấn

0: 480x640 1 class_0, 248.3ms
Speed: 5.0ms preprocess, 248.3ms inference, 2.0ms postprocess per image at shape (1, 3, 480, 640)
[2024/05/10 01:49:56] ppocr WARNING: Since the angle classifier is not initialized, it will not be used during the forward process
image/image_result/10-05-24/license/license2024-05-10-01-49-56.png
Lỗi:  ('23000', "[23000] [Microsoft][ODBC Driver 18 for SQL Server][SQL Server]Violation of PRIMARY KEY constraint 'PK__License___CAF38E519077C596'. Cannot insert duplicate key in object 'dbo.License_Plate'. The duplicate key value is (12-B1168.88). (2627) (SQLExecDirectW); [23000] [Microsoft][ODBC Driver 18 for SQL Server][SQL Server]The statement has been terminated. (3621)")
đã rollback ở ngoại lệ

0: 480x640 1 class_0, 212.0ms
Speed: 1.0ms preprocess, 212.0ms inference, 0.0ms postprocess per image at shape (1, 3, 480, 640)
[2024/05/10 01:50:06] ppocr WARNING: Since the angle classifier is not initialized, it will not be used during the forward process
image/image_result/10-05-24/license/license2024-05-10-01-50-07.png
Lỗi:  ('23000', "[23000] [Microsoft][ODBC Driver 18 for SQL Server][SQL Server]Violation of PRIMARY KEY constraint 'PK__License___CAF38E519077C596'. Cannot insert duplicate key in object 'dbo.License_Plate'. The duplicate key value is (12-B1168.88). (2627) (SQLExecDirectW); [23000] [Microsoft][ODBC Driver 18 for SQL Server][SQL Server]The statement has been terminated. (3621)")
đã rollback ở ngoại lệ

0: 480x640 1 class_0, 211.9ms
Speed: 2.0ms preprocess, 211.9ms inference, 1.1ms postprocess per image at shape (1, 3, 480, 640)
[2024/05/10 01:50:08] ppocr WARNING: Since the angle classifier is not initialized, it will not be used during the forward process
23000Exception in Tkinter callback
Traceback (most recent call last):
  File "C:\Program Files\WindowsApps\PythonSoftwareFoundation.Python.3.11_3.11.2544.0_x64__qbz5n2kfra8p0\Lib\tkinter\__init__.py", line 1967, in __call__
    return self.func(*args)
           ^^^^^^^^^^^^^^^^
  File "D:\Hieu\dacn\license_plate_app\tkButton.py", line 334, in get_license
    self.setup_IN_success()
  File "D:\Hieu\dacn\license_plate_app\tkButton.py", line 199, in setup_IN_success
    self.my_DB.info_insert_IN_onetime(self.id_card, self.now, self.license_plate, status="IN",result= "OK", lane=1, time_out= 0,
  File "D:\Hieu\dacn\license_plate_app\license_plate_DB.py", line 103, in info_insert_IN_onetime
    cursor.execute(info_insert_IN_onetime_quert, id_card, time_in, license_plate, result, lane, in_background, in_license,
pyodbc.IntegrityError: ('23000', "[23000] [Microsoft][ODBC Driver 18 for SQL Server][SQL Server]Violation of PRIMARY KEY constraint 'PK__License___CAF38E519077C596'. Cannot insert duplicate key in object 'dbo.License_Plate'. The duplicate key value is (12-B1168.88). (2627) (SQLExecDirectW); [23000] [Microsoft][ODBC Driver 18 for SQL Server][SQL Server]The statement has been terminated. (3621)")
23000Exception in Tkinter callback
Traceback (most recent call last):
  File "C:\Program Files\WindowsApps\PythonSoftwareFoundation.Python.3.11_3.11.2544.0_x64__qbz5n2kfra8p0\Lib\tkinter\__init__.py", line 1967, in __call__
    return self.func(*args)
           ^^^^^^^^^^^^^^^^
  File "D:\Hieu\dacn\license_plate_app\tkButton.py", line 334, in get_license
    self.setup_IN_success()
  File "D:\Hieu\dacn\license_plate_app\tkButton.py", line 199, in setup_IN_success
    self.my_DB.info_insert_IN_onetime(self.id_card, self.now, self.license_plate, status="IN",result= "OK", lane=1, time_out= 0,
  File "D:\Hieu\dacn\license_plate_app\license_plate_DB.py", line 103, in info_insert_IN_onetime
    cursor.execute(info_insert_IN_onetime_quert, id_card, time_in, license_plate, result, lane, in_background, in_license,
pyodbc.IntegrityError: ('23000', "[23000] [Microsoft][ODBC Driver 18 for SQL Server][SQL Server]Violation of PRIMARY KEY constraint 'PK__License___CAF38E519077C596'. Cannot insert duplicate key in object 'dbo.License_Plate'. The duplicate key value is (12-B1168.88). (2627) (SQLExecDirectW); [23000] [Microsoft][ODBC Driver 18 for SQL Server][SQL Server]The statement has been terminated. (3621)")
23000Exception in Tkinter callback
Traceback (most recent call last):
  File "C:\Program Files\WindowsApps\PythonSoftwareFoundation.Python.3.11_3.11.2544.0_x64__qbz5n2kfra8p0\Lib\tkinter\__init__.py", line 1967, in __call__
    return self.func(*args)
           ^^^^^^^^^^^^^^^^
  File "D:\Hieu\dacn\license_plate_app\tkButton.py", line 334, in get_license
    self.setup_IN_success()
  File "D:\Hieu\dacn\license_plate_app\tkButton.py", line 199, in setup_IN_success
    self.my_DB.info_insert_IN_onetime(self.id_card, self.now, self.license_plate, status="IN",result= "OK", lane=1, time_out= 0,
  File "D:\Hieu\dacn\license_plate_app\license_plate_DB.py", line 103, in info_insert_IN_onetime
    cursor.execute(info_insert_IN_onetime_quert, id_card, time_in, license_plate, result, lane, in_background, in_license,
pyodbc.IntegrityError: ('23000', "[23000] [Microsoft][ODBC Driver 18 for SQL Server][SQL Server]Violation of PRIMARY KEY constraint 'PK__License___CAF38E519077C596'. Cannot insert duplicate key in object 'dbo.License_Plate'. The duplicate key value is (12-B1168.88). (2627) (SQLExecDirectW); [23000] [Microsoft][ODBC Driver 18 for SQL Server][SQL Server]The statement has been terminated. (3621)")
Exception in Tkinter callback
Traceback (most recent call last):
  File "C:\Program Files\WindowsApps\PythonSoftwareFoundation.Python.3.11_3.11.2544.0_x64__qbz5n2kfra8p0\Lib\tkinter\__init__.py", line 1967, in __call__
    return self.func(*args)
           ^^^^^^^^^^^^^^^^
  File "D:\Hieu\dacn\license_plate_app\tkButton.py", line 357, in open_Database
    showDB =  show_DB(self.my_DB)
             ^^^^^^^^^^^^^^^^^^^
  File "D:\Hieu\dacn\license_plate_app\show_database.py", line 51, in __init__
    self.refresh(data=self.data)
  File "D:\Hieu\dacn\license_plate_app\show_database.py", line 111, in refresh
    self.tv_DB.insert(parent='', index="end", iid=i, text='', values=(data[i][0], data[i][1],data[i][2],data[i][3], data[i][4], data[i][5], data[i][6]))
                                                                      ~~~~^^^
IndexError: list index out of range
Exception in Tkinter callback
Traceback (most recent call last):
  File "C:\Program Files\WindowsApps\PythonSoftwareFoundation.Python.3.11_3.11.2544.0_x64__qbz5n2kfra8p0\Lib\tkinter\__init__.py", line 1967, in __call__
    return self.func(*args)
           ^^^^^^^^^^^^^^^^
  File "D:\Hieu\dacn\license_plate_app\show_database.py", line 31, in <lambda>
    refresh_btn = tk.Button(self.search_gui, text=sys_refresh, cursor="hand2", command= lambda: self.refresh(1))
                                                                                                ^^^^^^^^^^^^^^^
  File "D:\Hieu\dacn\license_plate_app\show_database.py", line 111, in refresh
    self.tv_DB.insert(parent='', index="end", iid=i, text='', values=(data[i][0], data[i][1],data[i][2],data[i][3], data[i][4], data[i][5], data[i][6]))
                                                                      ~~~~^^^
IndexError: list index out of range
Exception in Tkinter callback
Traceback (most recent call last):
  File "C:\Program Files\WindowsApps\PythonSoftwareFoundation.Python.3.11_3.11.2544.0_x64__qbz5n2kfra8p0\Lib\tkinter\__init__.py", line 1967, in __call__
    return self.func(*args)
           ^^^^^^^^^^^^^^^^
  File "D:\Hieu\dacn\license_plate_app\show_database.py", line 31, in <lambda>
    refresh_btn = tk.Button(self.search_gui, text=sys_refresh, cursor="hand2", command= lambda: self.refresh(1))
                                                                                                ^^^^^^^^^^^^^^^
  File "D:\Hieu\dacn\license_plate_app\show_database.py", line 111, in refresh
    self.tv_DB.insert(parent='', index="end", iid=i, text='', values=(data[i][0], data[i][1],data[i][2],data[i][3], data[i][4], data[i][5], data[i][6]))
                                                                      ~~~~^^^
IndexError: list index out of range
Exception in Tkinter callback
Traceback (most recent call last):
  File "C:\Program Files\WindowsApps\PythonSoftwareFoundation.Python.3.11_3.11.2544.0_x64__qbz5n2kfra8p0\Lib\tkinter\__init__.py", line 1967, in __call__
    return self.func(*args)
           ^^^^^^^^^^^^^^^^
  File "D:\Hieu\dacn\license_plate_app\show_database.py", line 31, in <lambda>
    refresh_btn = tk.Button(self.search_gui, text=sys_refresh, cursor="hand2", command= lambda: self.refresh(1))
                                                                                                ^^^^^^^^^^^^^^^
  File "D:\Hieu\dacn\license_plate_app\show_database.py", line 111, in refresh
    self.tv_DB.insert(parent='', index="end", iid=i, text='', values=(data[i][0], data[i][1],data[i][2],data[i][3], data[i][4], data[i][5], data[i][6]))
                                                                      ~~~~^^^
IndexError: list index out of range
Exception in Tkinter callback
Traceback (most recent call last):
  File "C:\Program Files\WindowsApps\PythonSoftwareFoundation.Python.3.11_3.11.2544.0_x64__qbz5n2kfra8p0\Lib\tkinter\__init__.py", line 1967, in __call__
    return self.func(*args)
           ^^^^^^^^^^^^^^^^
  File "D:\Hieu\dacn\license_plate_app\show_database.py", line 31, in <lambda>
    refresh_btn = tk.Button(self.search_gui, text=sys_refresh, cursor="hand2", command= lambda: self.refresh(1))
                                                                                                ^^^^^^^^^^^^^^^
  File "D:\Hieu\dacn\license_plate_app\show_database.py", line 111, in refresh
    self.tv_DB.insert(parent='', index="end", iid=i, text='', values=(data[i][0], data[i][1],data[i][2],data[i][3], data[i][4], data[i][5], data[i][6]))
                                                                      ~~~~^^^
IndexError: list index out of range
Exception in Tkinter callback
Traceback (most recent call last):
  File "C:\Program Files\WindowsApps\PythonSoftwareFoundation.Python.3.11_3.11.2544.0_x64__qbz5n2kfra8p0\Lib\tkinter\__init__.py", line 1967, in __call__
    return self.func(*args)
           ^^^^^^^^^^^^^^^^
  File "D:\Hieu\dacn\license_plate_app\show_database.py", line 31, in <lambda>
    refresh_btn = tk.Button(self.search_gui, text=sys_refresh, cursor="hand2", command= lambda: self.refresh(1))
                                                                                                ^^^^^^^^^^^^^^^
  File "D:\Hieu\dacn\license_plate_app\show_database.py", line 111, in refresh
    self.tv_DB.insert(parent='', index="end", iid=i, text='', values=(data[i][0], data[i][1],data[i][2],data[i][3], data[i][4], data[i][5], data[i][6]))
                                                                      ~~~~^^^
IndexError: list index out of range
Exception in Tkinter callback
Traceback (most recent call last):
  File "C:\Program Files\WindowsApps\PythonSoftwareFoundation.Python.3.11_3.11.2544.0_x64__qbz5n2kfra8p0\Lib\tkinter\__init__.py", line 1967, in __call__
    return self.func(*args)
           ^^^^^^^^^^^^^^^^
  File "D:\Hieu\dacn\license_plate_app\show_database.py", line 31, in <lambda>
    refresh_btn = tk.Button(self.search_gui, text=sys_refresh, cursor="hand2", command= lambda: self.refresh(1))
                                                                                                ^^^^^^^^^^^^^^^
  File "D:\Hieu\dacn\license_plate_app\show_database.py", line 111, in refresh
    self.tv_DB.insert(parent='', index="end", iid=i, text='', values=(data[i][0], data[i][1],data[i][2],data[i][3], data[i][4], data[i][5], data[i][6]))
                                                                      ~~~~^^^
IndexError: list index out of range
Exception in Tkinter callback
Traceback (most recent call last):
  File "C:\Program Files\WindowsApps\PythonSoftwareFoundation.Python.3.11_3.11.2544.0_x64__qbz5n2kfra8p0\Lib\tkinter\__init__.py", line 1967, in __call__
    return self.func(*args)
           ^^^^^^^^^^^^^^^^
  File "D:\Hieu\dacn\license_plate_app\show_database.py", line 31, in <lambda>
    refresh_btn = tk.Button(self.search_gui, text=sys_refresh, cursor="hand2", command= lambda: self.refresh(1))
                                                                                                ^^^^^^^^^^^^^^^
  File "D:\Hieu\dacn\license_plate_app\show_database.py", line 111, in refresh
    self.tv_DB.insert(parent='', index="end", iid=i, text='', values=(data[i][0], data[i][1],data[i][2],data[i][3], data[i][4], data[i][5], data[i][6]))
                                                                      ~~~~^^^
IndexError: list index out of range
Exception in Tkinter callback
Traceback (most recent call last):
  File "C:\Program Files\WindowsApps\PythonSoftwareFoundation.Python.3.11_3.11.2544.0_x64__qbz5n2kfra8p0\Lib\tkinter\__init__.py", line 1967, in __call__
    return self.func(*args)
           ^^^^^^^^^^^^^^^^
  File "D:\Hieu\dacn\license_plate_app\show_database.py", line 31, in <lambda>
    refresh_btn = tk.Button(self.search_gui, text=sys_refresh, cursor="hand2", command= lambda: self.refresh(1))
                                                                                                ^^^^^^^^^^^^^^^
  File "D:\Hieu\dacn\license_plate_app\show_database.py", line 111, in refresh
    self.tv_DB.insert(parent='', index="end", iid=i, text='', values=(data[i][0], data[i][1],data[i][2],data[i][3], data[i][4], data[i][5], data[i][6]))
                                                                      ~~~~^^^
IndexError: list index out of range
Exception in Tkinter callback
Traceback (most recent call last):
  File "C:\Program Files\WindowsApps\PythonSoftwareFoundation.Python.3.11_3.11.2544.0_x64__qbz5n2kfra8p0\Lib\tkinter\__init__.py", line 1967, in __call__
    return self.func(*args)
           ^^^^^^^^^^^^^^^^
  File "D:\Hieu\dacn\license_plate_app\show_database.py", line 31, in <lambda>
    refresh_btn = tk.Button(self.search_gui, text=sys_refresh, cursor="hand2", command= lambda: self.refresh(1))
                                                                                                ^^^^^^^^^^^^^^^
  File "D:\Hieu\dacn\license_plate_app\show_database.py", line 111, in refresh
    self.tv_DB.insert(parent='', index="end", iid=i, text='', values=(data[i][0], data[i][1],data[i][2],data[i][3], data[i][4], data[i][5], data[i][6]))
                                                                      ~~~~^^^
IndexError: list index out of range
Exception in Tkinter callback
Traceback (most recent call last):
  File "C:\Program Files\WindowsApps\PythonSoftwareFoundation.Python.3.11_3.11.2544.0_x64__qbz5n2kfra8p0\Lib\tkinter\__init__.py", line 1967, in __call__
    return self.func(*args)
           ^^^^^^^^^^^^^^^^
  File "D:\Hieu\dacn\license_plate_app\show_database.py", line 31, in <lambda>
    refresh_btn = tk.Button(self.search_gui, text=sys_refresh, cursor="hand2", command= lambda: self.refresh(1))
                                                                                                ^^^^^^^^^^^^^^^
  File "D:\Hieu\dacn\license_plate_app\show_database.py", line 111, in refresh
    self.tv_DB.insert(parent='', index="end", iid=i, text='', values=(data[i][0], data[i][1],data[i][2],data[i][3], data[i][4], data[i][5], data[i][6]))
                                                                      ~~~~^^^
IndexError: list index out of range
Exception in Tkinter callback
Traceback (most recent call last):
  File "C:\Program Files\WindowsApps\PythonSoftwareFoundation.Python.3.11_3.11.2544.0_x64__qbz5n2kfra8p0\Lib\tkinter\__init__.py", line 1967, in __call__
    return self.func(*args)
           ^^^^^^^^^^^^^^^^
  File "D:\Hieu\dacn\license_plate_app\show_database.py", line 31, in <lambda>
    refresh_btn = tk.Button(self.search_gui, text=sys_refresh, cursor="hand2", command= lambda: self.refresh(1))
                                                                                                ^^^^^^^^^^^^^^^
  File "D:\Hieu\dacn\license_plate_app\show_database.py", line 111, in refresh
    self.tv_DB.insert(parent='', index="end", iid=i, text='', values=(data[i][0], data[i][1],data[i][2],data[i][3], data[i][4], data[i][5], data[i][6]))
                                                                      ~~~~^^^
IndexError: list index out of range
Exception in Tkinter callback
Traceback (most recent call last):
  File "C:\Program Files\WindowsApps\PythonSoftwareFoundation.Python.3.11_3.11.2544.0_x64__qbz5n2kfra8p0\Lib\tkinter\__init__.py", line 1967, in __call__
    return self.func(*args)
           ^^^^^^^^^^^^^^^^
  File "D:\Hieu\dacn\license_plate_app\show_database.py", line 31, in <lambda>
    refresh_btn = tk.Button(self.search_gui, text=sys_refresh, cursor="hand2", command= lambda: self.refresh(1))
                                                                                                ^^^^^^^^^^^^^^^
  File "D:\Hieu\dacn\license_plate_app\show_database.py", line 111, in refresh
    self.tv_DB.insert(parent='', index="end", iid=i, text='', values=(data[i][0], data[i][1],data[i][2],data[i][3], data[i][4], data[i][5], data[i][6]))
                                                                      ~~~~^^^
IndexError: list index out of range
Exception in Tkinter callback
Traceback (most recent call last):
  File "C:\Program Files\WindowsApps\PythonSoftwareFoundation.Python.3.11_3.11.2544.0_x64__qbz5n2kfra8p0\Lib\tkinter\__init__.py", line 1967, in __call__
    return self.func(*args)
           ^^^^^^^^^^^^^^^^
  File "D:\Hieu\dacn\license_plate_app\show_database.py", line 31, in <lambda>
    refresh_btn = tk.Button(self.search_gui, text=sys_refresh, cursor="hand2", command= lambda: self.refresh(1))
                                                                                                ^^^^^^^^^^^^^^^
  File "D:\Hieu\dacn\license_plate_app\show_database.py", line 111, in refresh
    self.tv_DB.insert(parent='', index="end", iid=i, text='', values=(data[i][0], data[i][1],data[i][2],data[i][3], data[i][4], data[i][5], data[i][6]))
                                                                      ~~~~^^^
IndexError: list index out of range
image/image_result/10-05-24/license/license2024-05-10-01-50-08.png
Lỗi:  ('23000', "[23000] [Microsoft][ODBC Driver 18 for SQL Server][SQL Server]Violation of PRIMARY KEY constraint 'PK__License___CAF38E519077C596'. Cannot insert duplicate key in object 'dbo.License_Plate'. The duplicate key value is (12-B1168.88). (2627) (SQLExecDirectW); [23000] [Microsoft][ODBC Driver 18 for SQL Server][SQL Server]The statement has been terminated. (3621)")
đã rollback ở ngoại lệ
Đã kết nối tới CSDL và sẵn sàng truy vấn

0: 480x640 1 class_0, 248.3ms
Speed: 3.3ms preprocess, 248.3ms inference, 1.0ms postprocess per image at shape (1, 3, 480, 640)
[2024/05/10 01:59:44] ppocr WARNING: Since the angle classifier is not initialized, it will not be used during the forward process
Exception in Tkinter callback
Traceback (most recent call last):
  File "C:\Program Files\WindowsApps\PythonSoftwareFoundation.Python.3.11_3.11.2544.0_x64__qbz5n2kfra8p0\Lib\tkinter\__init__.py", line 1967, in __call__
    return self.func(*args)
           ^^^^^^^^^^^^^^^^
  File "D:\Hieu\dacn\license_plate_app\tkButton.py", line 357, in open_Database
    showDB =  show_DB(self.my_DB)
             ^^^^^^^^^^^^^^^^^^^
  File "D:\Hieu\dacn\license_plate_app\show_database.py", line 51, in __init__
    self.refresh(data=self.data)
  File "D:\Hieu\dacn\license_plate_app\show_database.py", line 111, in refresh
    self.tv_DB.insert(parent='', index="end", iid=i, text='', values=(data[i][0], data[i][1],data[i][2],data[i][3], data[i][4], data[i][5], data[i][6]))
                                                                      ~~~~^^^
IndexError: list index out of range
Exception in Tkinter callback
Traceback (most recent call last):
  File "C:\Program Files\WindowsApps\PythonSoftwareFoundation.Python.3.11_3.11.2544.0_x64__qbz5n2kfra8p0\Lib\tkinter\__init__.py", line 1967, in __call__
    return self.func(*args)
           ^^^^^^^^^^^^^^^^
  File "C:\Program Files\WindowsApps\PythonSoftwareFoundation.Python.3.11_3.11.2544.0_x64__qbz5n2kfra8p0\Lib\tkinter\__init__.py", line 861, in callit
    func(*args)
  File "D:\Hieu\dacn\license_plate_app\tkCamera.py", line 53, in update_frame
    width = self.canvas.winfo_width()
            ^^^^^^^^^^^^^^^^^^^^^^^^^
  File "C:\Program Files\WindowsApps\PythonSoftwareFoundation.Python.3.11_3.11.2544.0_x64__qbz5n2kfra8p0\Lib\tkinter\__init__.py", line 1356, in winfo_width
    self.tk.call('winfo', 'width', self._w))
    ^^^^^^^^^^^^^^^^^^^^^^^^^^^^^^^^^^^^^^^
_tkinter.TclError: can't invoke "winfo" command: application has been destroyed
image/image_result/10-05-24/license/license2024-05-10-01-59-44.png
