Exception in Tkinter callback
Traceback (most recent call last):
  File "C:\Program Files\WindowsApps\PythonSoftwareFoundation.Python.3.11_3.11.2544.0_x64__qbz5n2kfra8p0\Lib\tkinter\__init__.py", line 1967, in __call__
    return self.func(*args)
           ^^^^^^^^^^^^^^^^
  File "D:\Hieu\dacn\license_plate_app\tkButton.py", line 357, in open_Database
    showDB =  show_DB(self.my_DB)
             ^^^^^^^^^^^^^^^^^^^
  File "D:\Hieu\dacn\license_plate_app\show_database.py", line 57, in __init__
    self.refresh(data=self.data)
  File "D:\Hieu\dacn\license_plate_app\show_database.py", line 117, in refresh
    self.tv_DB.insert(parent='', index="end", iid=i, text='', values=(data[i][0], data[i][1],data[i][2],data[i][3], data[i][4], data[i][5], data[i][6]))\
                                                                      ~~~~^^^
IndexError: list index out of range
Exception in Tkinter callback
Traceback (most recent call last):
  File "C:\Program Files\WindowsApps\PythonSoftwareFoundation.Python.3.11_3.11.2544.0_x64__qbz5n2kfra8p0\Lib\tkinter\__init__.py", line 1967, in __call__
    return self.func(*args)
           ^^^^^^^^^^^^^^^^
TypeError: show_DB.validate_date() takes 2 positional arguments but 3 were given
Exception in Tkinter callback
Traceback (most recent call last):
  File "C:\Program Files\WindowsApps\PythonSoftwareFoundation.Python.3.11_3.11.2544.0_x64__qbz5n2kfra8p0\Lib\tkinter\__init__.py", line 1967, in __call__
    return self.func(*args)
           ^^^^^^^^^^^^^^^^
TypeError: show_DB.validate_date() takes 2 positional arguments but 3 were given
Exception in Tkinter callback
Traceback (most recent call last):
  File "C:\Program Files\WindowsApps\PythonSoftwareFoundation.Python.3.11_3.11.2544.0_x64__qbz5n2kfra8p0\Lib\tkinter\__init__.py", line 1967, in __call__
    return self.func(*args)
           ^^^^^^^^^^^^^^^^
Exception in Tkinter callback
Traceback (most recent call last):
  File "C:\Program Files\WindowsApps\PythonSoftwareFoundation.Python.3.11_3.11.2544.0_x64__qbz5n2kfra8p0\Lib\tkinter\__init__.py", line 1967, in __call__
    return self.func(*args)
           ^^^^^^^^^^^^^^^^
Đã kết nối tới CSDL và sẵn sàng truy vấn
Traceback (most recent call last):
  File "C:\Program Files\WindowsApps\PythonSoftwareFoundation.Python.3.11_3.11.2544.0_x64__qbz5n2kfra8p0\Lib\tkinter\__init__.py", line 1967, in __call__
    return self.func(*args)
           ^^^^^^^^^^^^^^^^
  File "D:\Hieu\dacn\license_plate_app\show_database.py", line 34, in <lambda>
      File "D:\Hieu\dacn\license_plate_app\show_database.py", line 147, in search_CSDL_time
    self.refresh(data=data)
  File "D:\Hieu\dacn\license_plate_app\show_database.py", line 117, in refresh
    self.tv_DB.insert(parent='', index="end", iid=i, text='', values=(data[i][0], data[i][1],data[i][2],data[i][3], data[i][4], data[i][5], data[i][6]))\
                                                                      ~~~~^^^
IndexError: list index out of range

During handling of the above exception, another exception occurred:

Traceback (most recent call last):
  File "C:\Program Files\WindowsApps\PythonSoftwareFoundation.Python.3.11_3.11.2544.0_x64__qbz5n2kfra8p0\Lib\tkinter\__init__.py", line 1967, in __call__
    return self.func(*args)
           ^^^^^^^^^^^^^^^^
  File "D:\Hieu\dacn\license_plate_app\main.py", line 104, in callback
    App(tkinter.Tk(), "SmartVN", sources)
  File "D:\Hieu\dacn\license_plate_app\main.py", line 44, in __init__
    self.window.mainloop()
  File "C:\Program Files\WindowsApps\PythonSoftwareFoundation.Python.3.11_3.11.2544.0_x64__qbz5n2kfra8p0\Lib\tkinter\__init__.py", line 1504, in mainloop
    self.tk.mainloop(n)
  File "C:\Program Files\WindowsApps\PythonSoftwareFoundation.Python.3.11_3.11.2544.0_x64__qbz5n2kfra8p0\Lib\tkinter\__init__.py", line 1971, in __call__
    self.widget._report_exception()
  File "C:\Program Files\WindowsApps\PythonSoftwareFoundation.Python.3.11_3.11.2544.0_x64__qbz5n2kfra8p0\Lib\tkinter\__init__.py", line 1687, in _report_exception
    root.report_callback_exception(exc, val, tb)
  File "C:\Program Files\WindowsApps\PythonSoftwareFoundation.Python.3.11_3.11.2544.0_x64__qbz5n2kfra8p0\Lib\tkinter\__init__.py", line 2425, in report_callback_exception
    traceback.print_exception(exc, val, tb)
  File "C:\Program Files\WindowsApps\PythonSoftwareFoundation.Python.3.11_3.11.2544.0_x64__qbz5n2kfra8p0\Lib\traceback.py", line 125, in print_exception
    te.print(file=file, chain=chain)
  File "C:\Program Files\WindowsApps\PythonSoftwareFoundation.Python.3.11_3.11.2544.0_x64__qbz5n2kfra8p0\Lib\traceback.py", line 1022, in print
    print(line, file=file, end="")
  File "C:\Program Files\WindowsApps\PythonSoftwareFoundation.Python.3.11_3.11.2544.0_x64__qbz5n2kfra8p0\Lib\encodings\cp1252.py", line 19, in encode
    return codecs.charmap_encode(input,self.errors,encoding_table)[0]
           ^^^^^^^^^^^^^^^^^^^^^^^^^^^^^^^^^^^^^^^^^^^^^^^^^^^^^^^
UnicodeEncodeError: 'charmap' codec can't encode character '\u1ebf' in position 141: character maps to <undefined>

During handling of the above exception, another exception occurred:

Traceback (most recent call last):
  File "D:\Hieu\dacn\license_plate_app\main.py", line 108, in <module>
    Start()
  File "D:\Hieu\dacn\license_plate_app\main.py", line 87, in __init__
    self.window.mainloop()
  File "C:\Program Files\WindowsApps\PythonSoftwareFoundation.Python.3.11_3.11.2544.0_x64__qbz5n2kfra8p0\Lib\tkinter\__init__.py", line 1504, in mainloop
    self.tk.mainloop(n)
  File "C:\Program Files\WindowsApps\PythonSoftwareFoundation.Python.3.11_3.11.2544.0_x64__qbz5n2kfra8p0\Lib\tkinter\__init__.py", line 1971, in __call__
    self.widget._report_exception()
  File "C:\Program Files\WindowsApps\PythonSoftwareFoundation.Python.3.11_3.11.2544.0_x64__qbz5n2kfra8p0\Lib\tkinter\__init__.py", line 1687, in _report_exception
    root.report_callback_exception(exc, val, tb)
  File "C:\Program Files\WindowsApps\PythonSoftwareFoundation.Python.3.11_3.11.2544.0_x64__qbz5n2kfra8p0\Lib\tkinter\__init__.py", line 2425, in report_callback_exception
    traceback.print_exception(exc, val, tb)
  File "C:\Program Files\WindowsApps\PythonSoftwareFoundation.Python.3.11_3.11.2544.0_x64__qbz5n2kfra8p0\Lib\traceback.py", line 125, in print_exception
    te.print(file=file, chain=chain)
  File "C:\Program Files\WindowsApps\PythonSoftwareFoundation.Python.3.11_3.11.2544.0_x64__qbz5n2kfra8p0\Lib\traceback.py", line 1022, in print
    print(line, file=file, end="")
  File "C:\Program Files\WindowsApps\PythonSoftwareFoundation.Python.3.11_3.11.2544.0_x64__qbz5n2kfra8p0\Lib\encodings\cp1252.py", line 19, in encode
    return codecs.charmap_encode(input,self.errors,encoding_table)[0]
           ^^^^^^^^^^^^^^^^^^^^^^^^^^^^^^^^^^^^^^^^^^^^^^^^^^^^^^^
UnicodeEncodeError: 'charmap' codec can't encode character '\u1ebf' in position 141: character maps to <undefined>
Exception in Tkinter callback
Traceback (most recent call last):
  File "C:\Program Files\WindowsApps\PythonSoftwareFoundation.Python.3.11_3.11.2544.0_x64__qbz5n2kfra8p0\Lib\tkinter\__init__.py", line 1967, in __call__
    return self.func(*args)
           ^^^^^^^^^^^^^^^^
TypeError: show_DB.validate_date() takes 2 positional arguments but 3 were given
Exception in Tkinter callback
Traceback (most recent call last):
  File "C:\Program Files\WindowsApps\PythonSoftwareFoundation.Python.3.11_3.11.2544.0_x64__qbz5n2kfra8p0\Lib\tkinter\__init__.py", line 1967, in __call__
    return self.func(*args)
           ^^^^^^^^^^^^^^^^
TypeError: show_DB.validate_date() takes 2 positional arguments but 3 were given
Exception in Tkinter callback
Traceback (most recent call last):
  File "C:\Program Files\WindowsApps\PythonSoftwareFoundation.Python.3.11_3.11.2544.0_x64__qbz5n2kfra8p0\Lib\tkinter\__init__.py", line 1967, in __call__
    return self.func(*args)
           ^^^^^^^^^^^^^^^^
  File "C:\Program Files\WindowsApps\PythonSoftwareFoundation.Python.3.11_3.11.2544.0_x64__qbz5n2kfra8p0\Lib\tkinter\__init__.py", line 861, in callit
    func(*args)
  File "D:\Hieu\dacn\license_plate_app\tkCamera.py", line 53, in update_frame
    width = self.canvas.winfo_width()
            ^^^^^^^^^^^^^^^^^^^^^^^^^
  File "C:\Program Files\WindowsApps\PythonSoftwareFoundation.Python.3.11_3.11.2544.0_x64__qbz5n2kfra8p0\Lib\tkinter\__init__.py", line 1356, in winfo_width
    self.tk.call('winfo', 'width', self._w))
    ^^^^^^^^^^^^^^^^^^^^^^^^^^^^^^^^^^^^^^^
_tkinter.TclError: can't invoke "winfo" command: application has been destroyed
Đã kết nối tới CSDL và sẵn sàng truy vấn
